Workbook

Sheet Dashboard
B1: EVERLAST WELDERS — EXECUTIVE BOOKKEEPING ANALYTICS
B2: SAMPLE DATA for review — replace the blue input cells on each tab with Everlast's QuickBooks actuals. All dashboard figures update automatically.
B4: Report month (1–12): | C4: 9 | D4: =CHOOSE(ReportMonth,"January","February","March","April","May","June","July","August","September","October","November","December")&" 2026 · YTD view" -> September 2026 · YTD view
B6: NET REVENUE YTD | E6: GROSS MARGIN YTD | H6: OPERATING INCOME YTD | K6: CASH (MONTH-END) | N6: AR OVER 30 DAYS | Q6: DAYS TO CLOSE
B7: ='P&L Monthly'!N17 -> 6251200 | E7: ='P&L Monthly'!N31 -> 0.34838111 | H7: ='P&L Monthly'!N43 -> 204900 | K7: =INDEX('Balance & Cash'!$B$5:$M$5,ReportMonth) -> 368000 | N7: ='AR Aging'!H13 -> 0.13525068 | Q7: =INDEX('Close KPIs'!$B$5:$M$5,ReportMonth) -> 9
B9: ="vs prior year: "&IF('Prior Year 2025'!N6=0,"n/a",TEXT('P&L Monthly'!N17/'Prior Year 2025'!N6-1,"+0.0%;-0.0%")) -> vs prior year: +11.4% | E9: ="Gross profit "&TEXT('P&L Monthly'!N30,"$#,##0") -> Gross profit $2,177,800 | H9: ="Operating margin "&TEXT('P&L Monthly'!N44,"0.0%") -> Operating margin 3.3% | K9: ="Working capital "&TEXT(INDEX('Balance & Cash'!$B$9:$M$9,ReportMonth),"$#,##0") -> Working capital $1,956,000 | N9: ="Total AR "&TEXT('AR Aging'!G13,"$#,##0") -> Total AR $257,300 | Q9: ="Target "&'Close KPIs'!B8&" business days" -> Target 10 business days
B11: QUARTERLY SUMMARY 2026 | J11: PRODUCT LINE PERFORMANCE (YTD)
B12: Quarter | C12: Net revenue | D12: Gross profit | E12: Gross margin | F12: Opex | G12: Operating income | H12: Op. margin | J12: Product line | L12: Sales | M12: COGS | N12: Gross profit | O12: Margin | P12: Share
B13: Q1 2026 | C13: =SUMPRODUCT('P&L Monthly'!$B$17:$M$17*(INT(('P&L Monthly'!$B$3:$M$3-1)/3)+1=1)) -> 1980000 | D13: =SUMPRODUCT('P&L Monthly'!$B$30:$M$30*(INT(('P&L Monthly'!$B$3:$M$3-1)/3)+1=1)) -> 689700 | E13: =IF(C13=0,"",D13/C13) -> 0.34833333 | F13: =SUMPRODUCT('P&L Monthly'!$B$42:$M$42*(INT(('P&L Monthly'!$B$3:$M$3-1)/3)+1=1)) -> 645100 | G13: =SUMPRODUCT('P&L Monthly'!$B$43:$M$43*(INT(('P&L Monthly'!$B$3:$M$3-1)/3)+1=1)) -> 44600 | H13: =IF(C13=0,"",G13/C13) -> 0.022525253 | J13: ='P&L Monthly'!A6 -> MIG welders | L13: ='P&L Monthly'!N6 -> 1824900 | M13: ='P&L Monthly'!N20 -> 1058700 | N13: =L13-M13 -> 766200 | O13: =IF(L13=0,"",N13/L13) -> 0.41985862 | P13: =IF(SUM($L$13:$L$19)=0,"",L13/SUM($L$13:$L$19)) -> 0.2641911
B14: Q2 2026 | C14: =SUMPRODUCT('P&L Monthly'!$B$17:$M$17*(INT(('P&L Monthly'!$B$3:$M$3-1)/3)+1=2)) -> 2167100 | D14: =SUMPRODUCT('P&L Monthly'!$B$30:$M$30*(INT(('P&L Monthly'!$B$3:$M$3-1)/3)+1=2)) -> 755100 | E14: =IF(C14=0,"",D14/C14) -> 0.348438 | F14: =SUMPRODUCT('P&L Monthly'!$B$42:$M$42*(INT(('P&L Monthly'!$B$3:$M$3-1)/3)+1=2)) -> 666700 | G14: =SUMPRODUCT('P&L Monthly'!$B$43:$M$43*(INT(('P&L Monthly'!$B$3:$M$3-1)/3)+1=2)) -> 88400 | H14: =IF(C14=0,"",G14/C14) -> 0.040791842 | J14: ='P&L Monthly'!A7 -> TIG welders | L14: ='P&L Monthly'!N7 -> 1390200 | M14: ='P&L Monthly'!N21 -> 764600 | N14: =L14-M14 -> 625600 | O14: =IF(L14=0,"",N14/L14) -> 0.45000719 | P14: =IF(SUM($L$13:$L$19)=0,"",L14/SUM($L$13:$L$19)) -> 0.2012595
B15: Q3 2026 | C15: =SUMPRODUCT('P&L Monthly'!$B$17:$M$17*(INT(('P&L Monthly'!$B$3:$M$3-1)/3)+1=3)) -> 2104100 | D15: =SUMPRODUCT('P&L Monthly'!$B$30:$M$30*(INT(('P&L Monthly'!$B$3:$M$3-1)/3)+1=3)) -> 733000 | E15: =IF(C15=0,"",D15/C15) -> 0.34836747 | F15: =SUMPRODUCT('P&L Monthly'!$B$42:$M$42*(INT(('P&L Monthly'!$B$3:$M$3-1)/3)+1=3)) -> 661100 | G15: =SUMPRODUCT('P&L Monthly'!$B$43:$M$43*(INT(('P&L Monthly'!$B$3:$M$3-1)/3)+1=3)) -> 71900 | H15: =IF(C15=0,"",G15/C15) -> 0.03417138 | J15: ='P&L Monthly'!A8 -> Stick welders | L15: ='P&L Monthly'!N8 -> 391200 | M15: ='P&L Monthly'!N22 -> 234800 | N15: =L15-M15 -> 156400 | O15: =IF(L15=0,"",N15/L15) -> 0.3997955 | P15: =IF(SUM($L$13:$L$19)=0,"",L15/SUM($L$13:$L$19)) -> 0.056634093
B16: Q4 2026 | C16: =SUMPRODUCT('P&L Monthly'!$B$17:$M$17*(INT(('P&L Monthly'!$B$3:$M$3-1)/3)+1=4)) -> 0 | D16: =SUMPRODUCT('P&L Monthly'!$B$30:$M$30*(INT(('P&L Monthly'!$B$3:$M$3-1)/3)+1=4)) -> 0 | E16: =IF(C16=0,"",D16/C16) | F16: =SUMPRODUCT('P&L Monthly'!$B$42:$M$42*(INT(('P&L Monthly'!$B$3:$M$3-1)/3)+1=4)) -> 0 | G16: =SUMPRODUCT('P&L Monthly'!$B$43:$M$43*(INT(('P&L Monthly'!$B$3:$M$3-1)/3)+1=4)) -> 0 | H16: =IF(C16=0,"",G16/C16) | J16: ='P&L Monthly'!A9 -> Multi-process welders | L16: ='P&L Monthly'!N9 -> 1042200 | M16: ='P&L Monthly'!N23 -> 583800 | N16: =L16-M16 -> 458400 | O16: =IF(L16=0,"",N16/L16) -> 0.4398388 | P16: =IF(SUM($L$13:$L$19)=0,"",L16/SUM($L$13:$L$19)) -> 0.15087948
J17: ='P&L Monthly'!A10 -> Plasma cutters | L17: ='P&L Monthly'!N10 -> 1303100 | M17: ='P&L Monthly'!N24 -> 742700 | N17: =L17-M17 -> 560400 | O17: =IF(L17=0,"",N17/L17) -> 0.43005142 | P17: =IF(SUM($L$13:$L$19)=0,"",L17/SUM($L$13:$L$19)) -> 0.18865002
B18: CHANNEL MIX (YTD) | J18: ='P&L Monthly'!A11 -> Accessories & consumables | L18: ='P&L Monthly'!N11 -> 738600 | M18: ='P&L Monthly'!N25 -> 332400 | N18: =L18-M18 -> 406200 | O18: =IF(L18=0,"",N18/L18) -> 0.54995938 | P18: =IF(SUM($L$13:$L$19)=0,"",L18/SUM($L$13:$L$19)) -> 0.10692725
B19: Channel | D19: Sales | E19: Share | J19: ='P&L Monthly'!A12 -> Parts & repairs | L19: ='P&L Monthly'!N12 -> 217300 | M19: ='P&L Monthly'!N26 -> 87000 | N19: =L19-M19 -> 130300 | O19: =IF(L19=0,"",N19/L19) -> 0.59963185 | P19: =IF(SUM($L$13:$L$19)=0,"",L19/SUM($L$13:$L$19)) -> 0.03145856
B20: =Channels!A5 -> Website store | D20: =Channels!N5 -> 2647700 | E20: =IF(SUM($D$20:$D$23)=0,"",D20/SUM($D$20:$D$23)) -> 0.383308
B21: =Channels!A6 -> Amazon & marketplaces | D21: =Channels!N6 -> 1863700 | E21: =IF(SUM($D$20:$D$23)=0,"",D21/SUM($D$20:$D$23)) -> 0.26980818 | J21: WHAT TO WATCH
B22: =Channels!A7 -> Dealers & distributors | D22: =Channels!N7 -> 1912500 | E22: =IF(SUM($D$20:$D$23)=0,"",D22/SUM($D$20:$D$23)) -> 0.27687296 | J22: ="• Net revenue YTD is "&TEXT('P&L Monthly'!N17,"$#,##0")&IF('Prior Year 2025'!N6=0,"",", "&TEXT('P&L Monthly'!N17/'Prior Year 2025'!N6-1,"+0.0%;-0.0%")&" vs 2025.") -> • Net revenue YTD is $6,251,200, +11.4% vs 2025.
B23: =Channels!A8 -> Phone & direct | D23: =Channels!N8 -> 483600 | E23: =IF(SUM($D$20:$D$23)=0,"",D23/SUM($D$20:$D$23)) -> 0.070010858 | J23: ="• Highest-margin line: "&INDEX($J$13:$J$19,MATCH(MAX($O$13:$O$19),$O$13:$O$19,0))&" ("&TEXT(MAX($O$13:$O$19),"0.0%")&")." -> • Highest-margin line: Parts & repairs (60.0%).
J24: ="• Lowest-margin line: "&INDEX($J$13:$J$19,MATCH(MIN($O$13:$O$19),$O$13:$O$19,0))&" ("&TEXT(MIN($O$13:$O$19),"0.0%")&")." -> • Lowest-margin line: Stick welders (40.0%).
J25: ="• Inventory lines to reorder: "&COUNTIF(Inventory!F5:F11,"Reorder")&"; overstocked: "&COUNTIF(Inventory!F5:F11,"Overstock")&"." -> • Inventory lines to reorder: 1; overstocked: 1.
J26: ="• "&TEXT('AR Aging'!H13,"0.0%")&" of dealer receivables are over 30 days." -> • 13.5% of dealer receivables are over 30 days.
J27: ="• Close took "&INDEX('Close KPIs'!$B$5:$M$5,ReportMonth)&" business days vs a "&'Close KPIs'!B8&"-day target." -> • Close took 9 business days vs a 10-day target.
B80: Chart data (do not edit)
B81: Month | C81: Net revenue 2026 | D81: Net revenue 2025 | E81: Cash | F81: Accounts receivable | G81: Inventory | H81: Days to close | I81: Target | J81: Gross margin 2026
B82: Jan | C82: =IF('P&L Monthly'!B17=0,"",'P&L Monthly'!B17) -> 614300 | D82: ='Prior Year 2025'!B6 -> 550000 | E82: =N('Balance & Cash'!B5) -> 410000 | F82: =N('Balance & Cash'!B6) -> 218000 | G82: =N('Balance & Cash'!B7) -> 1420000 | H82: =N('Close KPIs'!B5) -> 14 | I82: ='Close KPIs'!$B$8 -> 10 | J82: =IF('P&L Monthly'!B17=0,"",'P&L Monthly'!B31) -> 0.35048022
B83: Feb | C83: =IF('P&L Monthly'!C17=0,"",'P&L Monthly'!C17) -> 649300 | D83: ='Prior Year 2025'!C6 -> 583000 | E83: =N('Balance & Cash'!C5) -> 385000 | F83: =N('Balance & Cash'!C6) -> 226000 | G83: =N('Balance & Cash'!C7) -> 1465000 | H83: =N('Close KPIs'!C5) -> 13 | I83: ='Close KPIs'!$B$8 -> 10 | J83: =IF('P&L Monthly'!C17=0,"",'P&L Monthly'!C31) -> 0.34621901
B84: Mar | C84: =IF('P&L Monthly'!D17=0,"",'P&L Monthly'!D17) -> 716400 | D84: ='Prior Year 2025'!D6 -> 648000 | E84: =N('Balance & Cash'!D5) -> 362000 | F84: =N('Balance & Cash'!D6) -> 241000 | G84: =N('Balance & Cash'!D7) -> 1510000 | H84: =N('Close KPIs'!D5) -> 12 | I84: ='Close KPIs'!$B$8 -> 10 | J84: =IF('P&L Monthly'!D17=0,"",'P&L Monthly'!D31) -> 0.34840871
B85: Apr | C85: =IF('P&L Monthly'!E17=0,"",'P&L Monthly'!E17) -> 755300 | D85: ='Prior Year 2025'!E6 -> 680000 | E85: =N('Balance & Cash'!E5) -> 398000 | F85: =N('Balance & Cash'!E6) -> 252000 | G85: =N('Balance & Cash'!E7) -> 1480000 | H85: =N('Close KPIs'!E5) -> 12 | I85: ='Close KPIs'!$B$8 -> 10 | J85: =IF('P&L Monthly'!E17=0,"",'P&L Monthly'!E31) -> 0.35032437
B86: May | C86: =IF('P&L Monthly'!F17=0,"",'P&L Monthly'!F17) -> 723800 | D86: ='Prior Year 2025'!F6 -> 648000 | E86: =N('Balance & Cash'!F5) -> 421000 | F86: =N('Balance & Cash'!F6) -> 247000 | G86: =N('Balance & Cash'!F7) -> 1455000 | H86: =N('Close KPIs'!F5) -> 11 | I86: ='Close KPIs'!$B$8 -> 10 | J86: =IF('P&L Monthly'!F17=0,"",'P&L Monthly'!F31) -> 0.3470572
B87: Jun | C87: =IF('P&L Monthly'!G17=0,"",'P&L Monthly'!G17) -> 688000 | D87: ='Prior Year 2025'!G6 -> 615000 | E87: =N('Balance & Cash'!G5) -> 404000 | F87: =N('Balance & Cash'!G6) -> 236000 | G87: =N('Balance & Cash'!G7) -> 1490000 | H87: =N('Close KPIs'!G5) -> 11 | I87: ='Close KPIs'!$B$8 -> 10 | J87: =IF('P&L Monthly'!G17=0,"",'P&L Monthly'!G31) -> 0.34781977
B88: Jul | C88: =IF('P&L Monthly'!H17=0,"",'P&L Monthly'!H17) -> 658700 | D88: ='Prior Year 2025'!H6 -> 595000 | E88: =N('Balance & Cash'!H5) -> 377000 | F88: =N('Balance & Cash'!H6) -> 229000 | G88: =N('Balance & Cash'!H7) -> 1560000 | H88: =N('Close KPIs'!H5) -> 10 | I88: ='Close KPIs'!$B$8 -> 10 | J88: =IF('P&L Monthly'!H17=0,"",'P&L Monthly'!H31) -> 0.3500835
B89: Aug | C89: =IF('P&L Monthly'!I17=0,"",'P&L Monthly'!I17) -> 700600 | D89: ='Prior Year 2025'!I6 -> 628000 | E89: =N('Balance & Cash'!I5) -> 352000 | F89: =N('Balance & Cash'!I6) -> 244000 | G89: =N('Balance & Cash'!I7) -> 1640000 | H89: =N('Close KPIs'!I5) -> 10 | I89: ='Close KPIs'!$B$8 -> 10 | J89: =IF('P&L Monthly'!I17=0,"",'P&L Monthly'!I31) -> 0.34713103
B90: Sep | C90: =IF('P&L Monthly'!J17=0,"",'P&L Monthly'!J17) -> 744800 | D90: ='Prior Year 2025'!J6 -> 667000 | E90: =N('Balance & Cash'!J5) -> 368000 | F90: =N('Balance & Cash'!J6) -> 261000 | G90: =N('Balance & Cash'!J7) -> 1715000 | H90: =N('Close KPIs'!J5) -> 9 | I90: ='Close KPIs'!$B$8 -> 10 | J90: =IF('P&L Monthly'!J17=0,"",'P&L Monthly'!J31) -> 0.34801289
B91: Oct | C91: =IF('P&L Monthly'!K17=0,"",'P&L Monthly'!K17) | D91: ='Prior Year 2025'!K6 -> 712000 | E91: =N('Balance & Cash'!K5) -> 0 | F91: =N('Balance & Cash'!K6) -> 0 | G91: =N('Balance & Cash'!K7) -> 0 | H91: =N('Close KPIs'!K5) -> 0 | I91: ='Close KPIs'!$B$8 -> 10 | J91: =IF('P&L Monthly'!K17=0,"",'P&L Monthly'!K31)
B92: Nov | C92: =IF('P&L Monthly'!L17=0,"",'P&L Monthly'!L17) | D92: ='Prior Year 2025'!L6 -> 790000 | E92: =N('Balance & Cash'!L5) -> 0 | F92: =N('Balance & Cash'!L6) -> 0 | G92: =N('Balance & Cash'!L7) -> 0 | H92: =N('Close KPIs'!L5) -> 0 | I92: ='Close KPIs'!$B$8 -> 10 | J92: =IF('P&L Monthly'!L17=0,"",'P&L Monthly'!L31)
B93: Dec | C93: =IF('P&L Monthly'!M17=0,"",'P&L Monthly'!M17) | D93: ='Prior Year 2025'!M6 -> 874000 | E93: =N('Balance & Cash'!M5) -> 0 | F93: =N('Balance & Cash'!M6) -> 0 | G93: =N('Balance & Cash'!M7) -> 0 | H93: =N('Close KPIs'!M5) -> 0 | I93: ='Close KPIs'!$B$8 -> 10 | J93: =IF('P&L Monthly'!M17=0,"",'P&L Monthly'!M31)
B95: AR bucket | C95: Amount
B96: Current | C96: ='AR Aging'!B13 -> 165000
B97: 1–30 | C97: ='AR Aging'!C13 -> 57500
...

Sheet How to use
A1: How to use this workbook
A2: Executive analytics for Everlast Welders' bookkeeping. Sample figures until replaced with QuickBooks actuals.
B4: Report month | C4: Change the yellow cell on the Dashboard (1–12). Every YTD figure, tile and comment updates to that month.
B5: Blue cells | C5: Inputs. Paste QuickBooks actuals over them each month after close.
B6: Black cells | C6: Formulas. Don't type over them.
B7: Green cells | C7: Pulled from another tab.
B8: Yellow cells | C8: Settings you can change, such as the report month, reorder thresholds and close target.
B9: Monthly update (after close) | C9: 1. P&L Monthly: enter the month's revenue, COGS and expenses by line. 2. Channels: enter sales by channel; the Check row should read 0. 3. Balance & Cash: enter month-end balances. 4. AR Aging and Inventory: paste the latest figures. 5. Close KPIs: enter business days to close. 6. Set the Dashboard report month.
B10: Reading the tiles | C10: Net revenue and change vs 2025; gross margin; operating income; month-end cash with working capital; share of dealer AR over 30 days; days to close vs target.
B11: Reading the charts | C11: Revenue line: solid blue is 2026, dashed grey 2025. Margin bars: longest bar is the most profitable line. Channel ring: share of sales. Balance lines: watch inventory rising faster than sales. AR bars: anything right of 1–30 days needs follow-up. Close bars: orange above the dashed line means the close ran late.
B12: Status colors | C12: Red = needs action (reorder, AR over 25% past 30 days, close over target). Amber = overstock. Green = on track.
B13: Data source | C13: Sample data for review. QuickBooks reports to use: Profit & Loss by Class (channels) and by Product line, Balance Sheet, A/R Aging Summary, Inventory Valuation Summary.

Sheet P&L Monthly
A1: Monthly P&L by product line — 2026
A2: SAMPLE FIGURES. Replace blue cells with QuickBooks actuals (Jan–Sep shown; Oct–Dec left blank to fill). Black cells are formulas.
A3: Month index (helper) | B3: 1 | C3: 2 | D3: 3 | E3: 4 | F3: 5 | G3: 6 | H3: 7 | I3: 8 | J3: 9 | K3: 10 | L3: 11 | M3: 12
A4: Line ($) | B4: Jan 2026 | C4: Feb 2026 | D4: Mar 2026 | E4: Apr 2026 | F4: May 2026 | G4: Jun 2026 | H4: Jul 2026 | I4: Aug 2026 | J4: Sep 2026 | K4: Oct 2026 | L4: Nov 2026 | M4: Dec 2026 | N4: YTD to report month | O4: FY 2026
A5: REVENUE BY PRODUCT LINE
A6: MIG welders | B6: 178500 | C6: 192800 | D6: 205800 | E6: 222700 | F6: 207900 | G6: 205500 | H6: 187400 | I6: 203700 | J6: 220600 | N6: =SUMPRODUCT($B6:$M6*($B$3:$M$3<=ReportMonth)) -> 1824900 | O6: =SUM(B6:M6) -> 1824900
A7: TIG welders | B7: 138700 | C7: 141100 | D7: 161600 | E7: 166300 | F7: 164800 | G7: 147400 | H7: 147200 | I7: 158300 | J7: 164800 | N7: =SUMPRODUCT($B7:$M7*($B$3:$M$3<=ReportMonth)) -> 1390200 | O7: =SUM(B7:M7) -> 1390200
A8: Stick welders | B8: 37500 | C8: 40900 | D8: 44600 | E8: 48700 | F8: 43600 | G8: 42800 | H8: 42200 | I8: 43600 | J8: 47300 | N8: =SUMPRODUCT($B8:$M8*($B$3:$M$3<=ReportMonth)) -> 391200 | O8: =SUM(B8:M8) -> 391200
A9: Multi-process welders | B9: 103000 | C9: 106900 | D9: 123600 | E9: 122200 | F9: 120000 | G9: 116300 | H9: 110400 | I9: 118700 | J9: 121100 | N9: =SUMPRODUCT($B9:$M9*($B$3:$M$3<=ReportMonth)) -> 1042200 | O9: =SUM(B9:M9) -> 1042200
A10: Plasma cutters | B10: 126200 | C10: 139000 | D10: 145500 | E10: 157500 | F10: 153000 | G10: 142500 | H10: 140800 | I10: 142600 | J10: 156000 | N10: =SUMPRODUCT($B10:$M10*($B$3:$M$3<=ReportMonth)) -> 1303100 | O10: =SUM(B10:M10) -> 1303100
A11: Accessories & consumables | B11: 74400 | C11: 74200 | D11: 85000 | E11: 91000 | F11: 85000 | G11: 82400 | H11: 76600 | I11: 83300 | J11: 86700 | N11: =SUMPRODUCT($B11:$M11*($B$3:$M$3<=ReportMonth)) -> 738600 | O11: =SUM(B11:M11) -> 738600
A12: Parts & repairs | B12: 20600 | C12: 22500 | D12: 25500 | E12: 26200 | F12: 25500 | G12: 23300 | H12: 23200 | I12: 24000 | J12: 26500 | N12: =SUMPRODUCT($B12:$M12*($B$3:$M$3<=ReportMonth)) -> 217300 | O12: =SUM(B12:M12) -> 217300
A13: Gross product sales | B13: =SUM(B6:B12) -> 678900 | C13: =SUM(C6:C12) -> 717400 | D13: =SUM(D6:D12) -> 791600 | E13: =SUM(E6:E12) -> 834600 | F13: =SUM(F6:F12) -> 799800 | G13: =SUM(G6:G12) -> 760200 | H13: =SUM(H6:H12) -> 727800 | I13: =SUM(I6:I12) -> 774200 | ... M13: =SUM(M6:M12) -> 0 | N13: =SUMPRODUCT($B13:$M13*($B$3:$M$3<=ReportMonth)) -> 6907500 | O13: =SUM(B13:M13) -> 6907500
A14: Returns & refunds (enter as positive) | B14: 17000 | C14: 17900 | D14: 19800 | E14: 20900 | F14: 20000 | G14: 19000 | H14: 18200 | I14: 19400 | J14: 20600 | N14: =SUMPRODUCT($B14:$M14*($B$3:$M$3<=ReportMonth)) -> 172800 | O14: =SUM(B14:M14) -> 172800
A15: Discounts & promotions (enter as positive) | B15: 20400 | C15: 21500 | D15: 23700 | E15: 25000 | F15: 24000 | G15: 22800 | H15: 21800 | I15: 23200 | J15: 24700 | N15: =SUMPRODUCT($B15:$M15*($B$3:$M$3<=ReportMonth)) -> 207100 | O15: =SUM(B15:M15) -> 207100
A16: Marketplace fees (enter as positive) | B16: 27200 | C16: 28700 | D16: 31700 | E16: 33400 | F16: 32000 | G16: 30400 | H16: 29100 | I16: 31000 | J16: 32900 | N16: =SUMPRODUCT($B16:$M16*($B$3:$M$3<=ReportMonth)) -> 276400 | O16: =SUM(B16:M16) -> 276400
A17: Net revenue | B17: =B13-SUM(B14:B16) -> 614300 | C17: =C13-SUM(C14:C16) -> 649300 | D17: =D13-SUM(D14:D16) -> 716400 | E17: =E13-SUM(E14:E16) -> 755300 | F17: =F13-SUM(F14:F16) -> 723800 | G17: =G13-SUM(G14:G16) -> 688000 | H17: =H13-SUM(H14:H16) -> 658700 | I17: =I13-SUM(I14:I16) -> 700600 | ... M17: =M13-SUM(M14:M16) -> 0 | N17: =SUMPRODUCT($B17:$M17*($B$3:$M$3<=ReportMonth)) -> 6251200 | O17: =SUM(B17:M17) -> 6251200
A19: COST OF GOODS SOLD (at landed cost)
A20: COGS – MIG welders | B20: 102500 | C20: 111800 | D20: 120600 | E20: 127900 | F20: 120600 | G20: 120400 | H20: 107600 | I20: 118100 | J20: 129200 | N20: =SUMPRODUCT($B20:$M20*($B$3:$M$3<=ReportMonth)) -> 1058700 | O20: =SUM(B20:M20) -> 1058700
A21: COGS – TIG welders | B21: 76300 | C21: 78400 | D21: 88000 | E21: 91500 | F21: 91500 | G21: 80300 | H21: 81000 | I21: 87900 | J21: 89700 | N21: =SUMPRODUCT($B21:$M21*($B$3:$M$3<=ReportMonth)) -> 764600 | O21: =SUM(B21:M21) -> 764600
A22: COGS – Stick welders | B22: 22700 | C22: 24300 | D22: 26800 | E22: 29500 | F22: 25900 | G22: 25700 | H22: 25600 | I22: 25900 | J22: 28400 | N22: =SUMPRODUCT($B22:$M22*($B$3:$M$3<=ReportMonth)) -> 234800 | O22: =SUM(B22:M22) -> 234800
A23: COGS – Multi-process welders | B23: 57100 | C23: 59900 | D23: 69900 | E23: 67700 | F23: 67200 | G23: 65800 | H23: 61200 | I23: 66500 | J23: 68500 | N23: =SUMPRODUCT($B23:$M23*($B$3:$M$3<=ReportMonth)) -> 583800 | O23: =SUM(B23:M23) -> 583800
A24: COGS – Plasma cutters | B24: 71900 | C24: 80000 | D24: 82100 | E24: 89800 | F24: 88100 | G24: 80400 | H24: 80300 | I24: 82100 | J24: 88000 | N24: =SUMPRODUCT($B24:$M24*($B$3:$M$3<=ReportMonth)) -> 742700 | O24: =SUM(B24:M24) -> 742700
A25: COGS – Accessories & consumables | B25: 33800 | C25: 33100 | D25: 38200 | E25: 41400 | F25: 37900 | G25: 37100 | H25: 34800 | I25: 37100 | J25: 39000 | N25: =SUMPRODUCT($B25:$M25*($B$3:$M$3<=ReportMonth)) -> 332400 | O25: =SUM(B25:M25) -> 332400
A26: COGS – Parts & repairs | B26: 8200 | C26: 9000 | D26: 10300 | E26: 10400 | F26: 10200 | G26: 9400 | H26: 9200 | I26: 9600 | J26: 10700 | N26: =SUMPRODUCT($B26:$M26*($B$3:$M$3<=ReportMonth)) -> 87000 | O26: =SUM(B26:M26) -> 87000
A27: Outbound shipping | B27: 23800 | C27: 25100 | D27: 27700 | E27: 29200 | F27: 28000 | G27: 26600 | H27: 25500 | I27: 27100 | J27: 28800 | N27: =SUMPRODUCT($B27:$M27*($B$3:$M$3<=ReportMonth)) -> 241800 | O27: =SUM(B27:M27) -> 241800
A28: Inventory adjustments & shrink | B28: 2700 | C28: 2900 | D28: 3200 | E28: 3300 | F28: 3200 | G28: 3000 | H28: 2900 | I28: 3100 | J28: 3300 | N28: =SUMPRODUCT($B28:$M28*($B$3:$M$3<=ReportMonth)) -> 27600 | O28: =SUM(B28:M28) -> 27600
A29: Total COGS | B29: =SUM(B20:B28) -> 399000 | C29: =SUM(C20:C28) -> 424500 | D29: =SUM(D20:D28) -> 466800 | E29: =SUM(E20:E28) -> 490700 | F29: =SUM(F20:F28) -> 472600 | G29: =SUM(G20:G28) -> 448700 | H29: =SUM(H20:H28) -> 428100 | I29: =SUM(I20:I28) -> 457400 | ... M29: =SUM(M20:M28) -> 0 | N29: =SUMPRODUCT($B29:$M29*($B$3:$M$3<=ReportMonth)) -> 4073400 | O29: =SUM(B29:M29) -> 4073400
A30: Gross profit | B30: =B17-B29 -> 215300 | C30: =C17-C29 -> 224800 | D30: =D17-D29 -> 249600 | E30: =E17-E29 -> 264600 | F30: =F17-F29 -> 251200 | G30: =G17-G29 -> 239300 | H30: =H17-H29 -> 230600 | I30: =I17-I29 -> 243200 | ... M30: =M17-M29 -> 0 | N30: =SUMPRODUCT($B30:$M30*($B$3:$M$3<=ReportMonth)) -> 2177800 | O30: =SUM(B30:M30) -> 2177800
A31: Gross margin % | B31: =IF(B17=0,"",B30/B17) -> 0.35048022 | C31: =IF(C17=0,"",C30/C17) -> 0.34621901 | D31: =IF(D17=0,"",D30/D17) -> 0.34840871 | E31: =IF(E17=0,"",E30/E17) -> 0.35032437 | F31: =IF(F17=0,"",F30/F17) -> 0.3470572 | G31: =IF(G17=0,"",G30/G17) -> 0.34781977 | H31: =IF(H17=0,"",H30/H17) -> 0.3500835 | I31: =IF(I17=0,"",I30/I17) -> 0.34713103 | ... O31: =IF(O17=0,"",O30/O17) -> 0.34838111
A33: OPERATING EXPENSES
A34: Advertising (digital & social) | B34: 40700 | C34: 43000 | D34: 47500 | E34: 50100 | F34: 48000 | G34: 45600 | H34: 43700 | I34: 46500 | J34: 49400 | N34: =SUMPRODUCT($B34:$M34*($B$3:$M$3<=ReportMonth)) -> 414500 | O34: =SUM(B34:M34) -> 414500
A35: Merchant & processing fees | B35: 14900 | C35: 15800 | D35: 17400 | E35: 18400 | F35: 17600 | G35: 16700 | H35: 16000 | I35: 17000 | J35: 18100 | N35: =SUMPRODUCT($B35:$M35*($B$3:$M$3<=ReportMonth)) -> 151900 | O35: =SUM(B35:M35) -> 151900
A36: Payroll | B36: 93600 | C36: 94500 | D36: 95500 | E36: 96400 | F36: 93600 | G36: 94500 | H36: 95500 | I36: 96400 | J36: 93600 | N36: =SUMPRODUCT($B36:$M36*($B$3:$M$3<=ReportMonth)) -> 853600 | O36: =SUM(B36:M36) -> 853600
A37: Rent & warehouse | B37: 27600 | C37: 27900 | D37: 28100 | E37: 28400 | F37: 27600 | G37: 27900 | H37: 28100 | I37: 28400 | J37: 27600 | N37: =SUMPRODUCT($B37:$M37*($B$3:$M$3<=ReportMonth)) -> 251600 | O37: =SUM(B37:M37) -> 251600
A38: Warranty expense | B38: 10200 | C38: 10800 | D38: 11900 | E38: 12500 | F38: 12000 | G38: 11400 | H38: 10900 | I38: 11600 | J38: 12300 | N38: =SUMPRODUCT($B38:$M38*($B$3:$M$3<=ReportMonth)) -> 103600 | O38: =SUM(B38:M38) -> 103600
A39: Software & IT | B39: 5900 | C39: 6000 | D39: 6000 | E39: 6100 | F39: 5900 | G39: 6000 | H39: 6000 | I39: 6100 | J39: 5900 | N39: =SUMPRODUCT($B39:$M39*($B$3:$M$3<=ReportMonth)) -> 53900 | O39: =SUM(B39:M39) -> 53900
A40: Professional fees | B40: 8900 | C40: 9000 | D40: 9000 | E40: 9100 | F40: 8900 | G40: 9000 | H40: 9000 | I40: 9100 | J40: 8900 | N40: =SUMPRODUCT($B40:$M40*($B$3:$M$3<=ReportMonth)) -> 80900 | O40: =SUM(B40:M40) -> 80900
A41: Other operating | B41: 6900 | C41: 7000 | D41: 7000 | E41: 7100 | F41: 6900 | G41: 7000 | H41: 7000 | I41: 7100 | J41: 6900 | N41: =SUMPRODUCT($B41:$M41*($B$3:$M$3<=ReportMonth)) -> 62900 | O41: =SUM(B41:M41) -> 62900
A42: Total operating expenses | B42: =SUM(B34:B41) -> 208700 | C42: =SUM(C34:C41) -> 214000 | D42: =SUM(D34:D41) -> 222400 | E42: =SUM(E34:E41) -> 228100 | F42: =SUM(F34:F41) -> 220500 | G42: =SUM(G34:G41) -> 218100 | H42: =SUM(H34:H41) -> 216200 | I42: =SUM(I34:I41) -> 222200 | ... M42: =SUM(M34:M41) -> 0 | N42: =SUMPRODUCT($B42:$M42*($B$3:$M$3<=ReportMonth)) -> 1972900 | O42: =SUM(B42:M42) -> 1972900
...

Sheet Channels
A1: Gross product sales by channel — 2026
A2: SAMPLE FIGURES. Channel totals should equal Gross product sales on the P&L; the Check row flags any difference.
B3: 1 | C3: 2 | D3: 3 | E3: 4 | F3: 5 | G3: 6 | H3: 7 | I3: 8 | J3: 9 | K3: 10 | L3: 11 | M3: 12
A4: Channel ($) | B4: Jan 2026 | C4: Feb 2026 | D4: Mar 2026 | E4: Apr 2026 | F4: May 2026 | G4: Jun 2026 | H4: Jul 2026 | I4: Aug 2026 | J4: Sep 2026 | K4: Oct 2026 | L4: Nov 2026 | M4: Dec 2026 | N4: YTD to report month | O4: FY 2026
A5: Website store | B5: 258000 | C5: 279800 | D5: 300800 | E5: 317100 | F5: 311900 | G5: 288900 | H5: 276600 | I5: 301900 | J5: 312700 | N5: =SUMPRODUCT($B5:$M5*($B$3:$M$3<=ReportMonth)) -> 2647700 | O5: =SUM(B5:M5) -> 2647700
A6: Amazon & marketplaces | B6: 190100 | C6: 193700 | D6: 205800 | E6: 233700 | F6: 215900 | G6: 197700 | H6: 203800 | I6: 209000 | J6: 214000 | N6: =SUMPRODUCT($B6:$M6*($B$3:$M$3<=ReportMonth)) -> 1863700 | O6: =SUM(B6:M6) -> 1863700
A7: Dealers & distributors | B7: 183300 | C7: 193700 | D7: 229600 | E7: 225300 | F7: 215900 | G7: 220500 | H7: 196500 | I7: 209000 | J7: 238700 | N7: =SUMPRODUCT($B7:$M7*($B$3:$M$3<=ReportMonth)) -> 1912500 | O7: =SUM(B7:M7) -> 1912500
A8: Phone & direct | B8: 47500 | C8: 50200 | D8: 55400 | E8: 58500 | F8: 56100 | G8: 53100 | H8: 50900 | I8: 54300 | J8: 57600 | N8: =SUMPRODUCT($B8:$M8*($B$3:$M$3<=ReportMonth)) -> 483600 | O8: =SUM(B8:M8) -> 483600
A9: Total | B9: =SUM(B5:B8) -> 678900 | C9: =SUM(C5:C8) -> 717400 | D9: =SUM(D5:D8) -> 791600 | E9: =SUM(E5:E8) -> 834600 | F9: =SUM(F5:F8) -> 799800 | G9: =SUM(G5:G8) -> 760200 | H9: =SUM(H5:H8) -> 727800 | I9: =SUM(I5:I8) -> 774200 | ... M9: =SUM(M5:M8) -> 0 | N9: =SUMPRODUCT($B9:$M9*($B$3:$M$3<=ReportMonth)) -> 6907500 | O9: =SUM(B9:M9) -> 6907500
A10: Check vs P&L gross sales (should be 0) | B10: =B9-'P&L Monthly'!B13 -> 0 | C10: =C9-'P&L Monthly'!C13 -> 0 | D10: =D9-'P&L Monthly'!D13 -> 0 | E10: =E9-'P&L Monthly'!E13 -> 0 | F10: =F9-'P&L Monthly'!F13 -> 0 | G10: =G9-'P&L Monthly'!G13 -> 0 | H10: =H9-'P&L Monthly'!H13 -> 0 | I10: =I9-'P&L Monthly'!I13 -> 0 | ... M10: =M9-'P&L Monthly'!M13 -> 0

Sheet Prior Year 2025
A1: Prior year comparison — 2025
A2: SAMPLE FIGURES. Enter 2025 actuals from QuickBooks for year-over-year comparison.
B3: 1 | C3: 2 | D3: 3 | E3: 4 | F3: 5 | G3: 6 | H3: 7 | I3: 8 | J3: 9 | K3: 10 | L3: 11 | M3: 12
A4: Line ($) | B4: Jan 2025 | C4: Feb 2025 | D4: Mar 2025 | E4: Apr 2025 | F4: May 2025 | G4: Jun 2025 | H4: Jul 2025 | I4: Aug 2025 | J4: Sep 2025 | K4: Oct 2025 | L4: Nov 2025 | M4: Dec 2025 | N4: YTD to report month | O4: FY 2025
A5: Gross product sales | B5: 608000 | C5: 644000 | D5: 716000 | E5: 751000 | F5: 716000 | G5: 680000 | H5: 658000 | I5: 694000 | J5: 737000 | K5: 787000 | L5: 873000 | M5: 966000 | N5: =SUMPRODUCT($B5:$M5*($B$3:$M$3<=ReportMonth)) -> 6204000 | O5: =SUM(B5:M5) -> 8830000
A6: Net revenue | B6: 550000 | C6: 583000 | D6: 648000 | E6: 680000 | F6: 648000 | G6: 615000 | H6: 595000 | I6: 628000 | J6: 667000 | K6: 712000 | L6: 790000 | M6: 874000 | N6: =SUMPRODUCT($B6:$M6*($B$3:$M$3<=ReportMonth)) -> 5614000 | O6: =SUM(B6:M6) -> 7990000
A7: Gross profit | B7: 204000 | C7: 216000 | D7: 240000 | E7: 251000 | F7: 240000 | G7: 228000 | H7: 220000 | I7: 232000 | J7: 247000 | K7: 264000 | L7: 292000 | M7: 323000 | N7: =SUMPRODUCT($B7:$M7*($B$3:$M$3<=ReportMonth)) -> 2078000 | O7: =SUM(B7:M7) -> 2957000

Sheet Balance & Cash
A1: Month-end balances — 2026
A2: SAMPLE FIGURES. Enter month-end balances from the QuickBooks balance sheet.
A4: Balance ($) | B4: Jan 2026 | C4: Feb 2026 | D4: Mar 2026 | E4: Apr 2026 | F4: May 2026 | G4: Jun 2026 | H4: Jul 2026 | I4: Aug 2026 | J4: Sep 2026 | K4: Oct 2026 | L4: Nov 2026 | M4: Dec 2026
A5: Cash | B5: 410000 | C5: 385000 | D5: 362000 | E5: 398000 | F5: 421000 | G5: 404000 | H5: 377000 | I5: 352000 | J5: 368000
A6: Accounts receivable (dealers) | B6: 218000 | C6: 226000 | D6: 241000 | E6: 252000 | F6: 247000 | G6: 236000 | H6: 229000 | I6: 244000 | J6: 261000
A7: Inventory at landed cost | B7: 1420000 | C7: 1465000 | D7: 1510000 | E7: 1480000 | F7: 1455000 | G7: 1490000 | H7: 1560000 | I7: 1640000 | J7: 1715000
A8: Accounts payable | B8: 305000 | C8: 322000 | D8: 341000 | E8: 318000 | F8: 309000 | G8: 326000 | H8: 354000 | I8: 372000 | J8: 388000
A9: Working capital (cash + AR + inventory − AP) | B9: =IF(COUNT(B5:B8)=0,"",B5+B6+B7-B8) -> 1743000 | C9: =IF(COUNT(C5:C8)=0,"",C5+C6+C7-C8) -> 1754000 | D9: =IF(COUNT(D5:D8)=0,"",D5+D6+D7-D8) -> 1772000 | E9: =IF(COUNT(E5:E8)=0,"",E5+E6+E7-E8) -> 1812000 | F9: =IF(COUNT(F5:F8)=0,"",F5+F6+F7-F8) -> 1814000 | G9: =IF(COUNT(G5:G8)=0,"",G5+G6+G7-G8) -> 1804000 | H9: =IF(COUNT(H5:H8)=0,"",H5+H6+H7-H8) -> 1812000 | I9: =IF(COUNT(I5:I8)=0,"",I5+I6+I7-I8) -> 1864000 | ... M9: =IF(COUNT(M5:M8)=0,"",M5+M6+M7-M8)

Sheet AR Aging
A1: Dealer receivables aging — as of Sep 30, 2026
A2: SAMPLE FIGURES with placeholder dealer names. Paste the QuickBooks A/R Aging Summary here.
A4: Dealer | B4: Current | C4: 1–30 days | D4: 31–60 days | E4: 61–90 days | F4: 90+ days | G4: Total | H4: % over 30 days
A5: Dealer A | B5: 42000 | C5: 18000 | D5: 6000 | E5: 0 | F5: 0 | G5: =SUM(B5:F5) -> 66000 | H5: =IF(G5=0,"",SUM(D5:F5)/G5) -> 0.090909091
A6: Dealer B | B6: 31000 | C6: 9000 | D6: 4500 | E6: 2500 | F6: 0 | G6: =SUM(B6:F6) -> 47000 | H6: =IF(G6=0,"",SUM(D6:F6)/G6) -> 0.14893617
A7: Dealer C | B7: 27000 | C7: 12000 | D7: 0 | E7: 0 | F7: 0 | G7: =SUM(B7:F7) -> 39000 | H7: =IF(G7=0,"",SUM(D7:F7)/G7) -> 0
A8: Dealer D | B8: 19000 | C8: 6500 | D8: 7800 | E8: 3200 | F8: 1900 | G8: =SUM(B8:F8) -> 38400 | H8: =IF(G8=0,"",SUM(D8:F8)/G8) -> 0.3359375
A9: Dealer E | B9: 16500 | C9: 4200 | D9: 0 | E9: 0 | F9: 0 | G9: =SUM(B9:F9) -> 20700 | H9: =IF(G9=0,"",SUM(D9:F9)/G9) -> 0
A10: Dealer F | B10: 12000 | C10: 3100 | D10: 2600 | E10: 0 | F10: 0 | G10: =SUM(B10:F10) -> 17700 | H10: =IF(G10=0,"",SUM(D10:F10)/G10) -> 0.14689266
A11: Dealer G | B11: 9500 | C11: 2800 | D11: 1500 | E11: 1200 | F11: 3600 | G11: =SUM(B11:F11) -> 18600 | H11: =IF(G11=0,"",SUM(D11:F11)/G11) -> 0.33870968
A12: Dealer H | B12: 8000 | C12: 1900 | D12: 0 | E12: 0 | F12: 0 | G12: =SUM(B12:F12) -> 9900 | H12: =IF(G12=0,"",SUM(D12:F12)/G12) -> 0
A13: Total | B13: =SUM(B5:B12) -> 165000 | C13: =SUM(C5:C12) -> 57500 | D13: =SUM(D5:D12) -> 22400 | E13: =SUM(E5:E12) -> 6900 | F13: =SUM(F5:F12) -> 5500 | G13: =SUM(G5:G12) -> 257300 | H13: =IF(G13=0,"",SUM(D13:F13)/G13) -> 0.13525068

Sheet Inventory
A1: Inventory health by product line — as of Sep 30, 2026
A2: SAMPLE FIGURES. Weeks of cover = units on hand ÷ average weekly units sold. Under 6 weeks = reorder; over 26 weeks = overstock.
A3: Reorder below (weeks) | B3: 6 | C3: Overstock above (weeks) | D3: 26
A4: Product line | B4: Units on hand | C4: Avg units sold / month (last 3 mo) | D4: Stock value at landed cost | E4: Weeks of cover | F4: Status | G4: Share of stock value
A5: MIG welders | B5: 380 | C5: 310 | D5: 160000 | E5: =IF(C5=0,"",B5/(C5*12/52)) -> 5.311828 | F5: =IF(E5="","",IF(E5<$B$3,"Reorder",IF(E5>$D$3,"Overstock","OK"))) -> Reorder | G5: =IF($D$12=0,"",D5/$D$12) -> 0.1130742
A6: TIG welders | B6: 820 | C6: 190 | D6: 355000 | E6: =IF(C6=0,"",B6/(C6*12/52)) -> 18.701754 | F6: =IF(E6="","",IF(E6<$B$3,"Reorder",IF(E6>$D$3,"Overstock","OK"))) -> OK | G6: =IF($D$12=0,"",D6/$D$12) -> 0.25088339
A7: Stick welders | B7: 640 | C7: 120 | D7: 96000 | E7: =IF(C7=0,"",B7/(C7*12/52)) -> 23.111111 | F7: =IF(E7="","",IF(E7<$B$3,"Reorder",IF(E7>$D$3,"Overstock","OK"))) -> OK | G7: =IF($D$12=0,"",D7/$D$12) -> 0.067844523
A8: Multi-process welders | B8: 390 | C8: 150 | D8: 250000 | E8: =IF(C8=0,"",B8/(C8*12/52)) -> 11.266667 | F8: =IF(E8="","",IF(E8<$B$3,"Reorder",IF(E8>$D$3,"Overstock","OK"))) -> OK | G8: =IF($D$12=0,"",D8/$D$12) -> 0.17667845
A9: Plasma cutters | B9: 560 | C9: 170 | D9: 300000 | E9: =IF(C9=0,"",B9/(C9*12/52)) -> 14.27451 | F9: =IF(E9="","",IF(E9<$B$3,"Reorder",IF(E9>$D$3,"Overstock","OK"))) -> OK | G9: =IF($D$12=0,"",D9/$D$12) -> 0.21201413
A10: Accessories & consumables | B10: 5200 | C10: 2100 | D10: 165000 | E10: =IF(C10=0,"",B10/(C10*12/52)) -> 10.730159 | F10: =IF(E10="","",IF(E10<$B$3,"Reorder",IF(E10>$D$3,"Overstock","OK"))) -> OK | G10: =IF($D$12=0,"",D10/$D$12) -> 0.11660777
A11: Parts & repairs | B11: 4400 | C11: 640 | D11: 89000 | E11: =IF(C11=0,"",B11/(C11*12/52)) -> 29.791667 | F11: =IF(E11="","",IF(E11<$B$3,"Reorder",IF(E11>$D$3,"Overstock","OK"))) -> Overstock | G11: =IF($D$12=0,"",D11/$D$12) -> 0.062897527
A12: Total | B12: =SUM(B5:B11) -> 12390 | C12: =SUM(C5:C11) -> 3680 | D12: =SUM(D5:D11) -> 1415000

Sheet Close KPIs
A1: Month-end close performance — 2026
A2: SAMPLE FIGURES. Business days taken to close each month; target is 10.
A4: Measure | B4: Jan 2026 | C4: Feb 2026 | D4: Mar 2026 | E4: Apr 2026 | F4: May 2026 | G4: Jun 2026 | H4: Jul 2026 | I4: Aug 2026 | J4: Sep 2026 | K4: Oct 2026 | L4: Nov 2026 | M4: Dec 2026
A5: Business days to close | B5: 14 | C5: 13 | D5: 12 | E5: 12 | F5: 11 | G5: 11 | H5: 10 | I5: 10 | J5: 9
A6: Target | B6: =$B$8 -> 10 | C6: =$B$8 -> 10 | D6: =$B$8 -> 10 | E6: =$B$8 -> 10 | F6: =$B$8 -> 10 | G6: =$B$8 -> 10 | H6: =$B$8 -> 10 | I6: =$B$8 -> 10 | ... M6: =$B$8 -> 10
A8: Target business days | B8: 10
